<robot name="propeller_cw" xmlns:xacro="http://www.ros.org/wiki/xacro">
	<xacro:macro name="propeller_cw" params="mesh_file_add parent_name link_name joint_name mass ixx iyy izz ixy ixz iyz px py pz">
		<link name="${link_name}">
			<visual>
				<origin xyz="0 0 0" rpy="0 0 0"/>
				<geometry>
					<mesh filename="${mesh_file_add}"/>
				</geometry>
			</visual>
			<collision>
				<origin xyz="0 0 0" rpy="0 0 0"/>
				<geometry>
					<mesh filename="${mesh_file_add}"/>
				</geometry>
			</collision>
			<inertial>
				<mass value="${mass}"/>
				<origin xyz="0 0 0" rpy="0 0 0"/>
				<inertia
		        	ixx="${ixx}" ixy="${ixy}" ixz="${ixz}"
		        	iyy="${iyy}" iyz="${iyz}"
		        	izz="${izz}"
		    	/>
			</inertial>
		</link>

		<joint name="${joint_name}" type="continuous">
			<origin xyz="${px} ${py} ${pz}" rpy="0 0 0"/>
			<parent link="${parent_name}"/>
			<child link="${link_name}"/>
			<axis xyz = "0 0 1"/>
			<!-- <limit velocity="${max_velocity}" effort="${max_effort}"/> -->
		</joint> 
	</xacro:macro>
</robot>